<?xml version="1.0" ?>
<robot name="duke_bot" xmlns:xacro="http://www.ros.org/wiki/xacro">

<xacro:include filename="$(find duke_bot_description)/urdf/materials.xacro" />
<xacro:include filename="$(find duke_bot_description)/urdf/duke_bot.trans" />
<xacro:include filename="$(find duke_bot_description)/urdf/duke_bot.gazebo" />
<link name="base_link">
  <inertial>
    <origin xyz="9.54855897193596e-05 0.000323474174875853 0.0027826964495654915" rpy="0 0 0"/>
    <mass value="0.024022839982053068"/>
    <inertia ixx="1.3e-05" iyy="1.3e-05" izz="2.7e-05" ixy="-1e-06" iyz="0.0" ixz="0.0"/>
  </inertial>
  <visual>
    <origin xyz="0 0 0" rpy="0 0 0"/>
    <geometry>
      <mesh filename="file://$(find duke_bot_description)/meshes/base_link.stl" scale="0.001 0.001 0.001"/>
    </geometry>
    <material name="silver"/>
  </visual>
  <collision>
    <origin xyz="0 0 0" rpy="0 0 0"/>
    <geometry>
      <mesh filename="file://$(find duke_bot_description)/meshes/base_link.stl" scale="0.001 0.001 0.001"/>
    </geometry>
  </collision>
</link>

<link name="top_surface_holder_2_1">
  <inertial>
    <origin xyz="-4.097049409630682e-07 2.030571672898343e-07 0.014999696449565478" rpy="0 0 0"/>
    <mass value="0.0034909997200175324"/>
    <inertia ixx="0.0" iyy="0.0" izz="0.0" ixy="0.0" iyz="0.0" ixz="0.0"/>
  </inertial>
  <visual>
    <origin xyz="0.018618 0.005615 -0.004783" rpy="0 0 0"/>
    <geometry>
      <mesh filename="file://$(find duke_bot_description)/meshes/top_surface_holder_2_1.stl" scale="0.001 0.001 0.001"/>
    </geometry>
    <material name="silver"/>
  </visual>
  <collision>
    <origin xyz="0.018618 0.005615 -0.004783" rpy="0 0 0"/>
    <geometry>
      <mesh filename="file://$(find duke_bot_description)/meshes/top_surface_holder_2_1.stl" scale="0.001 0.001 0.001"/>
    </geometry>
  </collision>
</link>

<link name="top_surface_holder_1_1">
  <inertial>
    <origin xyz="-1.8370984154747472e-07 -2.2943900293385944e-07 0.0149996964495655" rpy="0 0 0"/>
    <mass value="0.0034909997200175324"/>
    <inertia ixx="0.0" iyy="0.0" izz="0.0" ixy="-0.0" iyz="0.0" ixz="0.0"/>
  </inertial>
  <visual>
    <origin xyz="-0.014941 0.014204 -0.004783" rpy="0 0 0"/>
    <geometry>
      <mesh filename="file://$(find duke_bot_description)/meshes/top_surface_holder_1_1.stl" scale="0.001 0.001 0.001"/>
    </geometry>
    <material name="silver"/>
  </visual>
  <collision>
    <origin xyz="-0.014941 0.014204 -0.004783" rpy="0 0 0"/>
    <geometry>
      <mesh filename="file://$(find duke_bot_description)/meshes/top_surface_holder_1_1.stl" scale="0.001 0.001 0.001"/>
    </geometry>
  </collision>
</link>

<link name="top_surface_holder_3_1">
  <inertial>
    <origin xyz="-1.2996143577276298e-07 -3.709479228404533e-07 0.014999696449565489" rpy="0 0 0"/>
    <mass value="0.0034909997200175324"/>
    <inertia ixx="0.0" iyy="0.0" izz="0.0" ixy="0.0" iyz="0.0" ixz="0.0"/>
  </inertial>
  <visual>
    <origin xyz="-0.0056 -0.019154 -0.004783" rpy="0 0 0"/>
    <geometry>
      <mesh filename="file://$(find duke_bot_description)/meshes/top_surface_holder_3_1.stl" scale="0.001 0.001 0.001"/>
    </geometry>
    <material name="silver"/>
  </visual>
  <collision>
    <origin xyz="-0.0056 -0.019154 -0.004783" rpy="0 0 0"/>
    <geometry>
      <mesh filename="file://$(find duke_bot_description)/meshes/top_surface_holder_3_1.stl" scale="0.001 0.001 0.001"/>
    </geometry>
  </collision>
</link>

<link name="top_surface_1">
  <inertial>
    <origin xyz="-0.005359879159044118 -0.018976560817436677 0.002015328801815139" rpy="0 0 0"/>
    <mass value="0.011716397428823319"/>
    <inertia ixx="3e-06" iyy="3e-06" izz="7e-06" ixy="-0.0" iyz="0.0" ixz="-0.0"/>
  </inertial>
  <visual>
    <origin xyz="-0.0056 -0.019154 -0.034783" rpy="0 0 0"/>
    <geometry>
      <mesh filename="file://$(find duke_bot_description)/meshes/top_surface_1.stl" scale="0.001 0.001 0.001"/>
    </geometry>
    <material name="silver"/>
  </visual>
  <collision>
    <origin xyz="-0.0056 -0.019154 -0.034783" rpy="0 0 0"/>
    <geometry>
      <mesh filename="file://$(find duke_bot_description)/meshes/top_surface_1.stl" scale="0.001 0.001 0.001"/>
    </geometry>
  </collision>
</link>

<link name="lidar_1">
  <inertial>
    <origin xyz="0.0008383738246992993 -0.0008384140600943525 0.004987597496776942" rpy="0 0 0"/>
    <mass value="0.0045472047500446046"/>
    <inertia ixx="0.0" iyy="0.0" izz="0.0" ixy="0.0" iyz="-0.0" ixz="0.0"/>
  </inertial>
  <visual>
    <origin xyz="-0.000641 0.000222 -0.039783" rpy="0 0 0"/>
    <geometry>
      <mesh filename="file://$(find duke_bot_description)/meshes/lidar_1.stl" scale="0.001 0.001 0.001"/>
    </geometry>
    <material name="silver"/>
  </visual>
  <collision>
    <origin xyz="-0.000641 0.000222 -0.039783" rpy="0 0 0"/>
    <geometry>
      <mesh filename="file://$(find duke_bot_description)/meshes/lidar_1.stl" scale="0.001 0.001 0.001"/>
    </geometry>
  </collision>
</link>

<link name="motor_holder_1_1">
  <inertial>
    <origin xyz="-0.008486420552512978 0.0010897278578822153 -0.006738007055746277" rpy="0 0 0"/>
    <mass value="0.0005943127590983897"/>
    <inertia ixx="0.0" iyy="0.0" izz="0.0" ixy="0.0" iyz="-0.0" ixz="-0.0"/>
  </inertial>
  <visual>
    <origin xyz="-0.022406 -0.046059 -0.000783" rpy="0 0 0"/>
    <geometry>
      <mesh filename="file://$(find duke_bot_description)/meshes/motor_holder_1_1.stl" scale="0.001 0.001 0.001"/>
    </geometry>
    <material name="silver"/>
  </visual>
  <collision>
    <origin xyz="-0.022406 -0.046059 -0.000783" rpy="0 0 0"/>
    <geometry>
      <mesh filename="file://$(find duke_bot_description)/meshes/motor_holder_1_1.stl" scale="0.001 0.001 0.001"/>
    </geometry>
  </collision>
</link>

<link name="motor_holder_2_1">
  <inertial>
    <origin xyz="0.003299502174232416 -0.007893715999442892 -0.006738007055746277" rpy="0 0 0"/>
    <mass value="0.0005943127590983897"/>
    <inertia ixx="0.0" iyy="0.0" izz="0.0" ixy="0.0" iyz="0.0" ixz="0.0"/>
  </inertial>
  <visual>
    <origin xyz="0.050213 0.005657 -0.000783" rpy="0 0 0"/>
    <geometry>
      <mesh filename="file://$(find duke_bot_description)/meshes/motor_holder_2_1.stl" scale="0.001 0.001 0.001"/>
    </geometry>
    <material name="silver"/>
  </visual>
  <collision>
    <origin xyz="0.050213 0.005657 -0.000783" rpy="0 0 0"/>
    <geometry>
      <mesh filename="file://$(find duke_bot_description)/meshes/motor_holder_2_1.stl" scale="0.001 0.001 0.001"/>
    </geometry>
  </collision>
</link>

<link name="motor_holder_3_1">
  <inertial>
    <origin xyz="-0.005186966469112084 -0.006804034087772862 -0.006738007055746281" rpy="0 0 0"/>
    <mass value="0.0005943127590983897"/>
    <inertia ixx="0.0" iyy="0.0" izz="0.0" ixy="-0.0" iyz="-0.0" ixz="0.0"/>
  </inertial>
  <visual>
    <origin xyz="-0.040232 0.027894 -0.000783" rpy="0 0 0"/>
    <geometry>
      <mesh filename="file://$(find duke_bot_description)/meshes/motor_holder_3_1.stl" scale="0.001 0.001 0.001"/>
    </geometry>
    <material name="silver"/>
  </visual>
  <collision>
    <origin xyz="-0.040232 0.027894 -0.000783" rpy="0 0 0"/>
    <geometry>
      <mesh filename="file://$(find duke_bot_description)/meshes/motor_holder_3_1.stl" scale="0.001 0.001 0.001"/>
    </geometry>
  </collision>
</link>

<link name="n20_motor_1_1">
  <inertial>
    <origin xyz="0.0007687298639330025 0.0029638635268054714 0.004980668155199606" rpy="0 0 0"/>
    <mass value="0.017834183296614247"/>
    <inertia ixx="1e-06" iyy="0.0" izz="1e-06" ixy="-0.0" iyz="0.0" ixz="0.0"/>
  </inertial>
  <visual>
    <origin xyz="-0.013827 -0.046805 0.011217" rpy="0 0 0"/>
    <geometry>
      <mesh filename="file://$(find duke_bot_description)/meshes/n20_motor_1_1.stl" scale="0.001 0.001 0.001"/>
    </geometry>
    <material name="silver"/>
  </visual>
  <collision>
    <origin xyz="-0.013827 -0.046805 0.011217" rpy="0 0 0"/>
    <geometry>
      <mesh filename="file://$(find duke_bot_description)/meshes/n20_motor_1_1.stl" scale="0.001 0.001 0.001"/>
    </geometry>
  </collision>
</link>

<link name="n20_motor_2_1">
  <inertial>
    <origin xyz="-0.0029516770846398296 -0.000816220396482872 0.0049806681551996124" rpy="0 0 0"/>
    <mass value="0.017834183296614247"/>
    <inertia ixx="0.0" iyy="1e-06" izz="1e-06" ixy="-0.0" iyz="0.0" ixz="-0.0"/>
  </inertial>
  <visual>
    <origin xyz="0.046569 0.013459 0.011217" rpy="0 0 0"/>
    <geometry>
      <mesh filename="file://$(find duke_bot_description)/meshes/n20_motor_2_1.stl" scale="0.001 0.001 0.001"/>
    </geometry>
    <material name="silver"/>
  </visual>
  <collision>
    <origin xyz="0.046569 0.013459 0.011217" rpy="0 0 0"/>
    <geometry>
      <mesh filename="file://$(find duke_bot_description)/meshes/n20_motor_2_1.stl" scale="0.001 0.001 0.001"/>
    </geometry>
  </collision>
</link>

<link name="n20_motor_3_1">
  <inertial>
    <origin xyz="0.002147526407343482 -0.0021829245347714382 0.005018724743931371" rpy="0 0 0"/>
    <mass value="0.017834183296614247"/>
    <inertia ixx="1e-06" iyy="1e-06" izz="1e-06" ixy="0.0" iyz="-0.0" ixz="-0.0"/>
  </inertial>
  <visual>
    <origin xyz="-0.035297 0.03495 0.011217" rpy="0 0 0"/>
    <geometry>
      <mesh filename="file://$(find duke_bot_description)/meshes/n20_motor_3_1.stl" scale="0.001 0.001 0.001"/>
    </geometry>
    <material name="silver"/>
  </visual>
  <collision>
    <origin xyz="-0.035297 0.03495 0.011217" rpy="0 0 0"/>
    <geometry>
      <mesh filename="file://$(find duke_bot_description)/meshes/n20_motor_3_1.stl" scale="0.001 0.001 0.001"/>
    </geometry>
  </collision>
</link>

<link name="omni_wheel_1_1">
  <inertial>
    <origin xyz="-0.0009107726794966298 -0.0033974504948327405 -3.027244888445524e-07" rpy="0 0 0"/>
    <mass value="0.007322790160921375"/>
    <inertia ixx="1e-06" iyy="1e-06" izz="1e-06" ixy="0.0" iyz="0.0" ixz="-0.0"/>
  </inertial>
  <visual>
    <origin xyz="-0.02123 -0.07443 0.006217" rpy="0 0 0"/>
    <geometry>
      <mesh filename="file://$(find duke_bot_description)/meshes/omni_wheel_1_1.stl" scale="0.001 0.001 0.001"/>
    </geometry>
    <material name="silver"/>
  </visual>
  <collision>
    <origin xyz="-0.02123 -0.07443 0.006217" rpy="0 0 0"/>
    <geometry>
      <mesh filename="file://$(find duke_bot_description)/meshes/omni_wheel_1_1.stl" scale="0.001 0.001 0.001"/>
    </geometry>
  </collision>
</link>

<link name="omni_wheel_2_1">
  <inertial>
    <origin xyz="0.0033976805510785163 0.0009106360374820689 -3.043763801635971e-07" rpy="0 0 0"/>
    <mass value="0.007322790160921375"/>
    <inertia ixx="1e-06" iyy="1e-06" izz="1e-06" ixy="0.0" iyz="-0.0" ixz="0.0"/>
  </inertial>
  <visual>
    <origin xyz="0.074195 0.020861 0.006217" rpy="0 0 0"/>
    <geometry>
      <mesh filename="file://$(find duke_bot_description)/meshes/omni_wheel_2_1.stl" scale="0.001 0.001 0.001"/>
    </geometry>
    <material name="silver"/>
  </visual>
  <collision>
    <origin xyz="0.074195 0.020861 0.006217" rpy="0 0 0"/>
    <geometry>
      <mesh filename="file://$(find duke_bot_description)/meshes/omni_wheel_2_1.stl" scale="0.001 0.001 0.001"/>
    </geometry>
  </collision>
</link>

<link name="omni_wheel_3_1">
  <inertial>
    <origin xyz="-0.002486936407590054 0.0024869319581574886 -3.043763801679339e-07" rpy="0 0 0"/>
    <mass value="0.007322790160921375"/>
    <inertia ixx="1e-06" iyy="1e-06" izz="1e-06" ixy="-0.0" iyz="0.0" ixz="0.0"/>
  </inertial>
  <visual>
    <origin xyz="-0.05552 0.055173 0.006217" rpy="0 0 0"/>
    <geometry>
      <mesh filename="file://$(find duke_bot_description)/meshes/omni_wheel_3_1.stl" scale="0.001 0.001 0.001"/>
    </geometry>
    <material name="silver"/>
  </visual>
  <collision>
    <origin xyz="-0.05552 0.055173 0.006217" rpy="0 0 0"/>
    <geometry>
      <mesh filename="file://$(find duke_bot_description)/meshes/omni_wheel_3_1.stl" scale="0.001 0.001 0.001"/>
    </geometry>
  </collision>
</link>

<link name="ov_camera_1">
  <inertial>
    <origin xyz="-0.0022579398219568503 0.002951945188588923 0.01554416229830156" rpy="0 0 0"/>
    <mass value="0.0027092205032529094"/>
    <inertia ixx="0.0" iyy="0.0" izz="0.0" ixy="0.0" iyz="0.0" ixz="-0.0"/>
  </inertial>
  <visual>
    <origin xyz="0.022096 -0.022515 -0.004783" rpy="0 0 0"/>
    <geometry>
      <mesh filename="file://$(find duke_bot_description)/meshes/ov_camera_1.stl" scale="0.001 0.001 0.001"/>
    </geometry>
    <material name="silver"/>
  </visual>
  <collision>
    <origin xyz="0.022096 -0.022515 -0.004783" rpy="0 0 0"/>
    <geometry>
      <mesh filename="file://$(find duke_bot_description)/meshes/ov_camera_1.stl" scale="0.001 0.001 0.001"/>
    </geometry>
  </collision>
</link>

<link name="fake_camera_1">
  <inertial>
    <origin xyz="-0.0022579398219568503 0.002951945188588923 0.01554416229830156" rpy="0 0 0"/>
    <mass value="0.0027092205032529094"/>
    <inertia ixx="0.0" iyy="0.0" izz="0.0" ixy="0.0" iyz="0.0" ixz="-0.0"/>
  </inertial>
</link>

<joint name="top_surface_holder1_fix" type="fixed">
  <origin xyz="-0.018618 -0.005615 0.004783" rpy="0 0 0"/>
  <parent link="base_link"/>
  <child link="top_surface_holder_2_1"/>
</joint>

<joint name="top_surface_holder2_fix" type="fixed">
  <origin xyz="0.014941 -0.014204 0.004783" rpy="0 0 0"/>
  <parent link="base_link"/>
  <child link="top_surface_holder_1_1"/>
</joint>

<joint name="top_surface_holder3_fix" type="fixed">
  <origin xyz="0.0056 0.019154 0.004783" rpy="0 0 0"/>
  <parent link="base_link"/>
  <child link="top_surface_holder_3_1"/>
</joint>

<joint name="top_surface_fix" type="fixed">
  <origin xyz="0.0 0.0 0.03" rpy="0 0 0"/>
  <parent link="top_surface_holder_3_1"/>
  <child link="top_surface_1"/>
</joint>

<joint name="lidar_fix" type="fixed">
  <origin xyz="-0.004959 -0.019376 0.005" rpy="0 0 0"/>
  <parent link="top_surface_1"/>
  <child link="lidar_1"/>
</joint>

<joint name="motor1_holder_fix" type="fixed">
  <origin xyz="0.022406 0.046059 0.000783" rpy="0 0 0"/>
  <parent link="base_link"/>
  <child link="motor_holder_1_1"/>
</joint>

<joint name="motor2_holder_fix" type="fixed">
  <origin xyz="-0.050213 -0.005657 0.000783" rpy="0 0 0"/>
  <parent link="base_link"/>
  <child link="motor_holder_2_1"/>
</joint>

<joint name="motor3_holder_fix" type="fixed">
  <origin xyz="0.040232 -0.027894 0.000783" rpy="0 0 0"/>
  <parent link="base_link"/>
  <child link="motor_holder_3_1"/>
</joint>

<joint name="n20_motor1_fix" type="fixed">
  <origin xyz="-0.008579 0.000746 -0.012" rpy="0 0 0"/>
  <parent link="motor_holder_1_1"/>
  <child link="n20_motor_1_1"/>
</joint>

<joint name="n20_motor2_fix" type="fixed">
  <origin xyz="0.003644 -0.007802 -0.012" rpy="0 0 0"/>
  <parent link="motor_holder_2_1"/>
  <child link="n20_motor_2_1"/>
</joint>

<joint name="n20_motor3_fix" type="fixed">
  <origin xyz="-0.004935 -0.007056 -0.012" rpy="0 0 0"/>
  <parent link="motor_holder_3_1"/>
  <child link="n20_motor_3_1"/>
</joint>

<joint name="wheel1_joint" type="continuous">
  <origin xyz="0.007403 0.027625 0.005" rpy="0 0 0"/>
  <parent link="n20_motor_1_1"/>
  <child link="omni_wheel_1_1"/>
  <axis xyz="0.258819 0.965926 -0.0"/>
</joint>

<joint name="wheel2_joint" type="continuous">
  <origin xyz="-0.027626 -0.007402 0.005" rpy="0 0 0"/>
  <parent link="n20_motor_2_1"/>
  <child link="omni_wheel_2_1"/>
  <axis xyz="-0.965926 -0.258819 -0.0"/>
</joint>

<joint name="wheel3_joint" type="continuous">
  <origin xyz="0.020223 -0.020223 0.005" rpy="0 0 0"/>
  <parent link="n20_motor_3_1"/>
  <child link="omni_wheel_3_1"/>
  <axis xyz="0.707107 -0.707107 0.0"/>
</joint>

<joint name="camera_fix" type="fixed">
  <origin xyz="-0.022096 0.022515 0.004783" rpy="0 0 0"/>
  <parent link="base_link"/>
  <child link="ov_camera_1"/>
</joint>

<joint name="fake_camera_fix" type="fixed">
  <origin xyz="-0.022096 0.025 0.004783" rpy="0 0 2.36"/>
  <parent link="base_link"/>
  <child link="fake_camera_1"/>
</joint>

</robot>
